Workbook

Sheet A̳ssets
B3: Paleta de Cores
B5: # 9BC848 | C5: Xbox Color | E5: # E8E6E9 | F5: negative zone
B6: # 22C55E | C6: Xbox Color
B7: # 2AE6B1 | C7: Menus
B8: # 5BF6A8 | C8: Menus
B12: Logos | J12: ícones

Sheet B̳ases
A1: ID do Assinante | B1: Nome | C1: Plano | D1: Data de Início | E1: Renovação Automática | F1: Preço da Assinatura | G1: Tipo de Assinatura | H1: Passe de Temporada EA Play | I1: Preço do Passe EA Play | J1: Passe de Temporada Minecraft | K1: Preço do Passe Minecraft | L1: Valor do Cupom | M1: Valor Total
A2: 3231 | B2: João Silva | C2: Ultimate | D2: 45292 | E2: Sim | F2: 15 | G2: Mensal | H2: Sim | I2: 30 | J2: Sim | K2: 20 | L2: 5 | M2: 60
A3: 3232 | B3: Maria Oliveira | C3: Core | D3: 45306 | E3: Não | F3: 5 | G3: Anual | H3: Não | I3: - | J3: Não | K3: 0 | L3: 0 | M3: 5
A4: 3233 | B4: Lucas Fernandes | C4: Standard | D4: 45332 | E4: Sim | F4: 10 | G4: Trimestral | H4: Não | I4: - | J4: Sim | K4: 20 | L4: 10 | M4: 20
A5: 3234 | B5: Ana Souza | C5: Ultimate | D5: 45342 | E5: Não | F5: 15 | G5: Mensal | H5: Sim | I5: 30 | J5: Sim | K5: 20 | L5: 3 | M5: 62
A6: 3235 | B6: Pedro Gonçalves | C6: Core | D6: 45356 | E6: Sim | F6: 5 | G6: Mensal | H6: Não | I6: - | J6: Não | K6: 0 | L6: 1 | M6: 4
A7: 3236 | B7: Felipe Costa | C7: Standard | D7: 45353 | E7: Não | F7: 10 | G7: Mensal | H7: Não | I7: - | J7: Sim | K7: 20 | L7: 2 | M7: 28
A8: 3237 | B8: Camila Ribeiro | C8: Ultimate | D8: 45354 | E8: Sim | F8: 15 | G8: Trimestral | H8: Sim | I8: 30 | J8: Sim | K8: 20 | L8: 10 | M8: 55
A9: 3238 | B9: André Mendes | C9: Core | D9: 45355 | E9: Sim | F9: 5 | G9: Anual | H9: Não | I9: - | J9: Não | K9: 0 | L9: 0 | M9: 5
A10: 3239 | B10: Sofia Almeida | C10: Ultimate | D10: 45356 | E10: Não | F10: 15 | G10: Mensal | H10: Sim | I10: 30 | J10: Sim | K10: 20 | L10: 5 | M10: 60
A11: 3240 | B11: Bruno Martins | C11: Standard | D11: 45357 | E11: Sim | F11: 10 | G11: Trimestral | H11: Não | I11: - | J11: Sim | K11: 20 | L11: 15 | M11: 15
A12: 3241 | B12: Rita Castro | C12: Core | D12: 45358 | E12: Não | F12: 5 | G12: Mensal | H12: Não | I12: - | J12: Não | K12: 0 | L12: 1 | M12: 4
A13: 3242 | B13: Marco Túlio | C13: Ultimate | D13: 45359 | E13: Sim | F13: 15 | G13: Anual | H13: Sim | I13: 30 | J13: Sim | K13: 20 | L13: 20 | M13: 45
A14: 3243 | B14: Lívia Silveira | C14: Standard | D14: 45360 | E14: Não | F14: 10 | G14: Mensal | H14: Não | I14: - | J14: Sim | K14: 20 | L14: 10 | M14: 20
A15: 3244 | B15: Diogo Sousa | C15: Core | D15: 45361 | E15: Sim | F15: 5 | G15: Trimestral | H15: Não | I15: - | J15: Não | K15: 0 | L15: 0 | M15: 5
A16: 3245 | B16: Fernanda Lima | C16: Ultimate | D16: 45362 | E16: Não | F16: 15 | G16: Mensal | H16: Sim | I16: 30 | J16: Sim | K16: 20 | L16: 8 | M16: 57
A17: 3246 | B17: Caio Pereira | C17: Standard | D17: 45363 | E17: Sim | F17: 10 | G17: Anual | H17: Não | I17: - | J17: Sim | K17: 20 | L17: 12 | M17: 18
A18: 3247 | B18: Beatriz Gomes | C18: Core | D18: 45364 | E18: Não | F18: 5 | G18: Mensal | H18: Não | I18: - | J18: Não | K18: 0 | L18: 2 | M18: 3
A19: 3248 | B19: Cesar Oliveira | C19: Ultimate | D19: 45365 | E19: Sim | F19: 15 | G19: Trimestral | H19: Sim | I19: 30 | J19: Sim | K19: 20 | L19: 7 | M19: 58
A20: 3249 | B20: Débora Machado | C20: Standard | D20: 45366 | E20: Não | F20: 10 | G20: Mensal | H20: Não | I20: - | J20: Sim | K20: 20 | L20: 5 | M20: 25
A21: 3250 | B21: Eduardo Vargas | C21: Core | D21: 45367 | E21: Sim | F21: 5 | G21: Anual | H21: Não | I21: - | J21: Não | K21: 0 | L21: 0 | M21: 5
A22: 3251 | B22: Gabriela Santos | C22: Ultimate | D22: 45368 | E22: Não | F22: 15 | G22: Mensal | H22: Sim | I22: 30 | J22: Sim | K22: 20 | L22: 3 | M22: 62
A23: 3252 | B23: Henrique Dias | C23: Standard | D23: 45369 | E23: Sim | F23: 10 | G23: Trimestral | H23: Não | I23: - | J23: Sim | K23: 20 | L23: 15 | M23: 15
A24: 3253 | B24: Isabela Moreira | C24: Core | D24: 45370 | E24: Não | F24: 5 | G24: Mensal | H24: Não | I24: - | J24: Não | K24: 0 | L24: 1 | M24: 4
A25: 3254 | B25: Joaquim Barbosa | C25: Ultimate | D25: 45371 | E25: Sim | F25: 15 | G25: Anual | H25: Sim | I25: 30 | J25: Sim | K25: 20 | L25: 20 | M25: 45
A26: 3255 | B26: Lara Rocha | C26: Standard | D26: 45372 | E26: Não | F26: 10 | G26: Mensal | H26: Não | I26: - | J26: Sim | K26: 20 | L26: 10 | M26: 20
A27: 3256 | B27: Matheus Silva | C27: Core | D27: 45373 | E27: Sim | F27: 5 | G27: Trimestral | H27: Não | I27: - | J27: Não | K27: 0 | L27: 0 | M27: 5
A28: 3257 | B28: Nicole Costa | C28: Ultimate | D28: 45374 | E28: Não | F28: 15 | G28: Mensal | H28: Sim | I28: 30 | J28: Sim | K28: 20 | L28: 5 | M28: 60
A29: 3258 | B29: Otávio Mendonça | C29: Standard | D29: 45375 | E29: Sim | F29: 10 | G29: Anual | H29: Não | I29: - | J29: Sim | K29: 20 | L29: 15 | M29: 15
A30: 3259 | B30: Paula Ferreira | C30: Core | D30: 45376 | E30: Não | F30: 5 | G30: Mensal | H30: Não | I30: - | J30: Não | K30: 0 | L30: 1 | M30: 4
A31: 3260 | B31: Raquel Alves | C31: Ultimate | D31: 45377 | E31: Sim | F31: 15 | G31: Trimestral | H31: Sim | I31: 30 | J31: Sim | K31: 20 | L31: 7 | M31: 58
A32: 3261 | B32: Samuel Pires | C32: Standard | D32: 45378 | E32: Não | F32: 10 | G32: Mensal | H32: Não | I32: - | J32: Sim | K32: 20 | L32: 10 | M32: 20
A33: 3262 | B33: Tânia Barros | C33: Core | D33: 45379 | E33: Sim | F33: 5 | G33: Anual | H33: Não | I33: - | J33: Não | K33: 0 | L33: 0 | M33: 5
A34: 3263 | B34: Vinicius Lima | C34: Ultimate | D34: 45380 | E34: Não | F34: 15 | G34: Mensal | H34: Sim | I34: 30 | J34: Sim | K34: 20 | L34: 3 | M34: 62
A35: 3264 | B35: Yasmin Teixeira | C35: Standard | D35: 45381 | E35: Sim | F35: 10 | G35: Trimestral | H35: Não | I35: - | J35: Sim | K35: 20 | L35: 15 | M35: 15
A36: 3265 | B36: Zé Carlos | C36: Core | D36: 45382 | E36: Não | F36: 5 | G36: Mensal | H36: Não | I36: - | J36: Não | K36: 0 | L36: 1 | M36: 4
A37: 3266 | B37: Amanda Nogueira | C37: Core | D37: 45383 | E37: Sim | F37: 5 | G37: Mensal | H37: Não | I37: - | J37: Não | K37: 0 | L37: 0 | M37: 5
A38: 3267 | B38: Bruno Cavalheiro | C38: Ultimate | D38: 45384 | E38: Não | F38: 15 | G38: Trimestral | H38: Sim | I38: 30 | J38: Sim | K38: 20 | L38: 7 | M38: 58
A39: 3268 | B39: Carla Dias | C39: Standard | D39: 45385 | E39: Sim | F39: 10 | G39: Anual | H39: Não | I39: - | J39: Sim | K39: 20 | L39: 10 | M39: 20
A40: 3269 | B40: Diego Fontes | C40: Core | D40: 45386 | E40: Não | F40: 5 | G40: Trimestral | H40: Não | I40: - | J40: Não | K40: 0 | L40: 1 | M40: 4
...

Sheet C̳álculos
A1: Indicadores
A3: Assinantes | B3: =COUNTA('B̳ases'!$A$2:$A$296)
A4: Receita total | B4: =SUM('B̳ases'!$M$2:$M$296)
A5: Ticket médio | B5: =B4/B3
A6: Total em cupons | B6: =SUM('B̳ases'!$L$2:$L$296)
A7: % renovação automática | B7: =COUNTIF('B̳ases'!$E$2:$E$296,"Sim")/B3
A10: Por plano
A11: Plano | B11: Assinantes | C11: Receita
A12: Core | B12: =COUNTIF('B̳ases'!$C$2:$C$296,A12) | C12: =SUMIF('B̳ases'!$C$2:$C$296,A12,'B̳ases'!$M$2:$M$296)
A13: Standard | B13: =COUNTIF('B̳ases'!$C$2:$C$296,A13) | C13: =SUMIF('B̳ases'!$C$2:$C$296,A13,'B̳ases'!$M$2:$M$296)
A14: Ultimate | B14: =COUNTIF('B̳ases'!$C$2:$C$296,A14) | C14: =SUMIF('B̳ases'!$C$2:$C$296,A14,'B̳ases'!$M$2:$M$296)
A17: Por tipo de assinatura
A18: Tipo | B18: Assinantes | C18: Receita | D18: Chave
A19: Mensal | B19: =COUNTIF('B̳ases'!$G$2:$G$296,D19) | C19: =SUMIF('B̳ases'!$G$2:$G$296,D19,'B̳ases'!$M$2:$M$296) | D19: Mensal
A20: Trimestral | B20: =COUNTIF('B̳ases'!$G$2:$G$296,D20) | C20: =SUMIF('B̳ases'!$G$2:$G$296,D20,'B̳ases'!$M$2:$M$296) | D20: Trimestral
A21: Anual | B21: =COUNTIF('B̳ases'!$G$2:$G$296,D21) | C21: =SUMIF('B̳ases'!$G$2:$G$296,D21,'B̳ases'!$M$2:$M$296) | D21: Anual
A24: Renovação automática
A25: Renovação | B25: Assinantes | C25: Chave
A26: Com renovação | B26: =COUNTIF('B̳ases'!$E$2:$E$296,C26) | C26: Sim
A27: Sem renovação | B27: =COUNTIF('B̳ases'!$E$2:$E$296,C27) | C27: Não
A30: Passes adicionais
A31: Passe | B31: Assinantes | C31: Receita
A32: EA Play | B32: =COUNTIF('B̳ases'!$H$2:$H$296,"Sim") | C32: =SUM('B̳ases'!$I$2:$I$296)
A33: Por mês de início (2024) | B33: =COUNTIF('B̳ases'!$J$2:$J$296,"Sim") | C33: =SUM('B̳ases'!$K$2:$K$296)
A34: Mês | B34: Novas assinaturas | C34: Receita
A35: Jan | B35: =COUNTIFS('B̳ases'!$D$2:$D$296,">="&DATE(2024,1,1),'B̳ases'!$D$2:$D$296,"<"&DATE(2024,2,1)) | C35: =SUMIFS('B̳ases'!$M$2:$M$296,'B̳ases'!$D$2:$D$296,">="&DATE(2024,1,1),'B̳ases'!$D$2:$D$296,"<"&DATE(2024,2,1))
A36: Fev | B36: =COUNTIFS('B̳ases'!$D$2:$D$296,">="&DATE(2024,2,1),'B̳ases'!$D$2:$D$296,"<"&DATE(2024,3,1)) | C36: =SUMIFS('B̳ases'!$M$2:$M$296,'B̳ases'!$D$2:$D$296,">="&DATE(2024,2,1),'B̳ases'!$D$2:$D$296,"<"&DATE(2024,3,1))
A37: Mar | B37: =COUNTIFS('B̳ases'!$D$2:$D$296,">="&DATE(2024,3,1),'B̳ases'!$D$2:$D$296,"<"&DATE(2024,4,1)) | C37: =SUMIFS('B̳ases'!$M$2:$M$296,'B̳ases'!$D$2:$D$296,">="&DATE(2024,3,1),'B̳ases'!$D$2:$D$296,"<"&DATE(2024,4,1))
A38: Abr | B38: =COUNTIFS('B̳ases'!$D$2:$D$296,">="&DATE(2024,4,1),'B̳ases'!$D$2:$D$296,"<"&DATE(2024,5,1)) | C38: =SUMIFS('B̳ases'!$M$2:$M$296,'B̳ases'!$D$2:$D$296,">="&DATE(2024,4,1),'B̳ases'!$D$2:$D$296,"<"&DATE(2024,5,1))
A39: Mai | B39: =COUNTIFS('B̳ases'!$D$2:$D$296,">="&DATE(2024,5,1),'B̳ases'!$D$2:$D$296,"<"&DATE(2024,6,1)) | C39: =SUMIFS('B̳ases'!$M$2:$M$296,'B̳ases'!$D$2:$D$296,">="&DATE(2024,5,1),'B̳ases'!$D$2:$D$296,"<"&DATE(2024,6,1))
A40: Jun | B40: =COUNTIFS('B̳ases'!$D$2:$D$296,">="&DATE(2024,6,1),'B̳ases'!$D$2:$D$296,"<"&DATE(2024,7,1)) | C40: =SUMIFS('B̳ases'!$M$2:$M$296,'B̳ases'!$D$2:$D$296,">="&DATE(2024,6,1),'B̳ases'!$D$2:$D$296,"<"&DATE(2024,7,1))
A41: Jul | B41: =COUNTIFS('B̳ases'!$D$2:$D$296,">="&DATE(2024,7,1),'B̳ases'!$D$2:$D$296,"<"&DATE(2024,8,1)) | C41: =SUMIFS('B̳ases'!$M$2:$M$296,'B̳ases'!$D$2:$D$296,">="&DATE(2024,7,1),'B̳ases'!$D$2:$D$296,"<"&DATE(2024,8,1))
A42: Ago | B42: =COUNTIFS('B̳ases'!$D$2:$D$296,">="&DATE(2024,8,1),'B̳ases'!$D$2:$D$296,"<"&DATE(2024,9,1)) | C42: =SUMIFS('B̳ases'!$M$2:$M$296,'B̳ases'!$D$2:$D$296,">="&DATE(2024,8,1),'B̳ases'!$D$2:$D$296,"<"&DATE(2024,9,1))
A43: Set | B43: =COUNTIFS('B̳ases'!$D$2:$D$296,">="&DATE(2024,9,1),'B̳ases'!$D$2:$D$296,"<"&DATE(2024,10,1)) | C43: =SUMIFS('B̳ases'!$M$2:$M$296,'B̳ases'!$D$2:$D$296,">="&DATE(2024,9,1),'B̳ases'!$D$2:$D$296,"<"&DATE(2024,10,1))
A44: Out | B44: =COUNTIFS('B̳ases'!$D$2:$D$296,">="&DATE(2024,10,1),'B̳ases'!$D$2:$D$296,"<"&DATE(2024,11,1)) | C44: =SUMIFS('B̳ases'!$M$2:$M$296,'B̳ases'!$D$2:$D$296,">="&DATE(2024,10,1),'B̳ases'!$D$2:$D$296,"<"&DATE(2024,11,1))
A45: Nov | B45: =COUNTIFS('B̳ases'!$D$2:$D$296,">="&DATE(2024,11,1),'B̳ases'!$D$2:$D$296,"<"&DATE(2024,12,1)) | C45: =SUMIFS('B̳ases'!$M$2:$M$296,'B̳ases'!$D$2:$D$296,">="&DATE(2024,11,1),'B̳ases'!$D$2:$D$296,"<"&DATE(2024,12,1))
A46: Dez | B46: =COUNTIFS('B̳ases'!$D$2:$D$296,">="&DATE(2024,12,1),'B̳ases'!$D$2:$D$296,"<"&DATE(2025,1,1)) | C46: =SUMIFS('B̳ases'!$M$2:$M$296,'B̳ases'!$D$2:$D$296,">="&DATE(2024,12,1),'B̳ases'!$D$2:$D$296,"<"&DATE(2025,1,1))

Sheet D̳ashboard
B2: Xbox Game Pass | Dashboard de Vendas 2024
B3: Assinantes, receita e passes adicionais
B6: Assinantes | F6: Receita total | J6: Ticket médio | N6: Total em cupons | R6: Renovação automática
B7: ='C̳álculos'!B3 | F7: ='C̳álculos'!B4 | J7: ='C̳álculos'!B5 | N7: ='C̳álculos'!B6 | R7: ='C̳álculos'!B7
